#VRML_SIM R2022a utf8
WorldInfo {
  info [
    "In this example, the robot turns on a slope."
    "Its accelerometer sensor is used to switch on the bottommost LED."
  ]
  title "Accelerometer"
  basicTimeStep 8
  contactProperties [
    ContactProperties {
      material2 "body"
      coulombFriction [
        0
      ]
      softCFM 0.1
    }
  ]
}
Viewpoint {
  orientation 0.38533142098969314 0.16859605565250207 -0.9072458685585084 2.309857556582598
  position 1.327935805602493 1.660457159827752 1.8203425761217247
}
TexturedBackground {
}
TexturedBackgroundLight {
}
Floor {
  size 1 1
}
PointLight {
  attenuation 0 0 1
  intensity 0.6
  location 0.6 0 0
}
DEF WALL_1 Solid {
  translation 0.5 0 0.05
  children [
    DEF WALL_SHAPE Shape {
      appearance PBRAppearance {
        baseColor 0.8 0.8 0.8
        roughness 1
        metalness 0
      }
      geometry Box {
        size 0.02 0.98 0.1
      }
    }
  ]
  name "solid(1)"
  boundingObject USE WALL_SHAPE
}
DEF WALL_3 Solid {
  translation 0 -0.5 0.05
  rotation 0 0 1 1.5708
  children [
    USE WALL_SHAPE
  ]
  name "solid(3)"
  boundingObject USE WALL_SHAPE
}
DEF WALL_2 Solid {
  translation -0.5 0 0.05
  children [
    USE WALL_SHAPE
  ]
  name "solid(2)"
  boundingObject USE WALL_SHAPE
}
DEF WALL_4 Solid {
  translation 0 0.5 0.05
  rotation 0 0 1 1.5708
  children [
    USE WALL_SHAPE
  ]
  name "solid(4)"
  boundingObject USE WALL_SHAPE
}
Robot {
  translation -0.2775207083407934 -0.09497130960802472 0.03993024482462188
  rotation 6.899645248617526e-08 2.361784723627012e-08 0.9999999999999973 0.663293083665187
  children [
    DEF WHEEL1 HingeJoint {
      jointParameters HingeJointParameters {
        position 14.759992060451248
        axis 0 1 0
        anchor 0.05 0.06 0
      }
      device [
        RotationalMotor {
          name "wheel1"
        }
      ]
      endPoint Solid {
        translation 0.05 0.06 0
        rotation 0.3409982671135542 0.6647243548043319 -0.664726796477709 2.48432877836788
        children [
          DEF WHEEL Shape {
            appearance PBRAppearance {
              baseColor 0.305882 0.898039 0.25098
              roughness 1
              metalness 0
            }
            geometry Cylinder {
              height 0.02
              radius 0.04
              subdivision 24
            }
          }
        ]
        boundingObject USE WHEEL
        physics Physics {
        }
        linearVelocity 0.03151852610224376 0.024628470193462874 4.907745358851719e-09
        angularVelocity -0.6157149525992357 0.787968946632626 1.8437984802083596e-08
      }
    }
    DEF WHEEL2 HingeJoint {
      jointParameters HingeJointParameters {
        position 1.960006683276252
        axis 0 1 0
        anchor 0.05 -0.06 0
      }
      device [
        RotationalMotor {
          name "wheel2"
        }
      ]
      endPoint Solid {
        translation 0.05 -0.06 0
        rotation 0.4285117514291771 0.6388954062146807 -0.638897753012857 2.3319125766387265
        children [
          USE WHEEL
        ]
        name "solid(1)"
        boundingObject USE WHEEL
        physics Physics {
        }
        linearVelocity 0.03151888137461377 0.02462834351669208 -5.179240751120423e-09
        angularVelocity -0.6157149739780047 0.7879689503649777 2.1872150946823838e-08
      }
    }
    DEF WHEEL3 HingeJoint {
      jointParameters HingeJointParameters {
        position 14.759991556842692
        axis 0 1 0
        anchor -0.05 0.06 0
      }
      device [
        RotationalMotor {
          name "wheel3"
        }
      ]
      endPoint Solid {
        translation -0.05 0.06 0
        rotation 0.3409984539575038 0.664724306879769 -0.6647267485529696 2.48432844360702
        children [
          USE WHEEL
        ]
        name "solid(2)"
        boundingObject USE WHEEL
        physics Physics {
        }
        linearVelocity 0.03151863526981465 0.02462887201788166 5.17881607724089e-09
        angularVelocity -0.6157149612755534 0.7879689735971093 1.6716735370967372e-08
      }
    }
    DEF WHEEL4 HingeJoint {
      jointParameters HingeJointParameters {
        position 1.9600061401606037
        axis 0 1 0
        anchor -0.05 -0.06 0
      }
      device [
        RotationalMotor {
          name "wheel4"
        }
      ]
      endPoint Solid {
        translation -0.05 -0.06 0
        rotation 0.42851195678467807 0.6388953373482062 -0.6388976841461301 2.331912229644653
        children [
          USE WHEEL
        ]
        name "solid(3)"
        boundingObject USE WHEEL
        physics Physics {
        }
        linearVelocity 0.031518991086906055 0.024628709085181173 -4.9081700525936765e-09
        angularVelocity -0.6157149824811612 0.7879689752490198 2.0351538538664277e-08
      }
    }
    DEF DS_RIGHT DistanceSensor {
      translation 0.1 -0.03 0
      rotation 0 0 1 -0.3
      children [
        Shape {
          appearance PBRAppearance {
            baseColor 0.184314 0.596078 0.847059
            roughness 1
            metalness 0
          }
          geometry Box {
            size 0.01 0.01 0.01
          }
        }
      ]
      name "ds_right"
    }
    DEF DS_LEFT DistanceSensor {
      translation 0.1 0.03 0
      rotation 0 0 1 0.3
      children [
        Shape {
          appearance PBRAppearance {
            baseColor 0.184314 0.596078 0.847059
            roughness 1
            metalness 0
          }
          geometry Box {
            size 0.01 0.01 0.01
          }
        }
      ]
      name "ds_left"
    }
    DEF BODY Shape {
      appearance PBRAppearance {
        baseColor 0.917647 0.145098 0.145098
        roughness 1
        metalness 0
      }
      geometry Box {
        size 0.2 0.1 0.05
      }
    }
  ]
  boundingObject USE BODY
  physics Physics {
    mass 1
  }
  controller "four_wheels_collision_avoidance"
  linearVelocity 0.03151875846023309 0.024628598704740722 -2.1238572946087256e-13
  angularVelocity 6.585685323002039e-08 5.497061048926724e-08 -2.7744614557370755e-08
}
FourWheelsRobot {
}
